Workbook
Name Slicer_Month: #N/A
Name Slicer_Month1: #N/A
Name Slicer_Sector1: #N/A

Sheet Story Boarding
A1: Year | B1: 2023
A2: Month | B2: May
A4: Sum of Foods | B4: Sum of Fuel and light | C4: Sum of Luxury | D4: Sum of Clothings | E4: Sum of Housing Goods | F4: Sum of Health | G4: Sum of Transport and communication | H4: Sum of Miscellaneous | I4: Sum of Education | J4: Sum of General index
A5: 2112 | B5: 182.5 | C5: 737.3 | D5: 569.9 | E5: 355.4 | F5: 187.8 | G5: 169.7 | H5: 179.5 | I5: 180.3 | J5: 179.8
A6: Foods | B6: Fuel and light | C6: Luxury | D6: Clothings | E6: Housing Goods | F6: Health | G6: Transport and communication | H6: Miscellaneous | I6: Education
A7: =A5/SUM($A$5:$I$5)*100 -> 45.182269 | B7: =B5/SUM($A$5:$I$5)*100 -> 3.9042444 | C7: =C5/SUM($A$5:$I$5)*100 -> 15.773147 | D7: =D5/SUM($A$5:$I$5)*100 -> 12.191939 | E7: =E5/SUM($A$5:$I$5)*100 -> 7.6031148 | F7: =F5/SUM($A$5:$I$5)*100 -> 4.0176279 | G7: =G5/SUM($A$5:$I$5)*100 -> 3.6304125 | H7: =H5/SUM($A$5:$I$5)*100 -> 3.840065 | I7: =I5/SUM($A$5:$I$5)*100 -> 3.8571795
A8: CPI Contribution for different broader categories
A24: CPI Contribution for food is highest in the Inflation basket around 46%
A33: Problem Statement
A49: Sector | B49: Rural+Urban
A51: Row Labels | B51: Average of Foods | C51: Average of Clothings | D51: Average of Luxury | E51: Average of Housing Goods | F51: Average of Fuel and light | G51: Average of Health | H51: Average of Transport and communication | I51: Average of Education | J51: Average of Miscellaneous
A52: 2017 | B52: 1592 | C52: 406.8 | D52: 522.5 | E52: 263 | F52: 129.4 | G52: 128.4 | H52: 116.7 | I52: 134.8 | J52: 125.3
A53: 2018 | B53: 1629.9 | C53: 428.1 | D53: 549.5 | E53: 280.6 | F53: 136.9 | G53: 136 | H53: 122.9 | I53: 142.1 | J53: 132.1
A54: 2019 | B54: 1657.9 | C54: 436.1 | D54: 570.7 | E54: 293.8 | F54: 140.3 | G54: 146.9 | H54: 124.9 | I54: 151.6 | J54: 138.2
A55: 2020 | B55: 1850.63 | C55: 447.72 | D55: 614.54 | E55: 147.65 | F55: 144.16364 | G55: 154.28182 | H55: 136.09 | I55: 157.37 | J55: 147.61
A56: 2021 | B56: 1946.4 | C56: 474.3 | D56: 665.6 | E56: 316.3 | F56: 159.4 | G56: 165.8 | H56: 148.9 | I56: 161.2 | J56: 156.8
A57: 2022 | B57: 2071.8 | C57: 518.6 | D57: 694.7 | E57: 332.7 | F57: 174.6 | G57: 174.8 | H57: 163 | I57: 167.9 | J57: 167.5
A58: 2023 | B58: 2133.5 | C58: 553.2 | D58: 730.8 | E58: 350.8 | F58: 182.8 | G58: 185.7 | H58: 164.8 | I58: 177.1 | J58: 175.7
A59: Grand Total | B59: 1840.3043 | C59: 466.40286 | D59: 621.19143 | E59: 283.55 | F59: 152.50909 | G59: 155.98312 | H59: 139.61286 | I59: 156.01 | J59: 149.03
B63: Y-O-Y | C63: Yearly Inflation | E63: We can see that 2020-21 has the highest inflation rate
B64: 2017-18 | C64: 4.071485
B65: 2018-19 | C65: 2.87513
B66: 2019-20 | C66: 3.8153058
B67: 2020-21 | C67: 10.385231 | D67: Highest Inflation
B68: 2021-22 | C68: 6.4581496
B69: 2022-23 | C69: 4.2278753
A73: Reason for inflation according to the research
A77: The COVID-19 pandemic caused supply chain issues, which led to backlogs of work orders for goods and services , and the rise in inflation is mostly driven by food inflation.
A85: Problem Statement
A87: #VALUE!
A103: Year | B103: 2023
A105: Row Labels | B105: Average of Foods | D105: M-O-M | E105: Monthly Inflation
A106: January | B106: 2124.7 | D106: May-jun 22 | E106: 1.0820183 | F106: Highest Food Inflation
A107: February | B107: 2111.0667 | D107: June-july 22 | E107: 0.1778766
A108: March | B108: 2111.2 | D108: July-Aug 22 | E108: 0.10939011
A109: April | B109: 2121.6333 | D109: Aug-Sept 22 | E109: 0.54793653
A110: May | B110: 2138.2333 | D110: Sept-Oct 22 | E110: 0.74970075
A111: Grand Total | B111: 2121.3667 | D111: Oct-Nov 22 | E111: -0.10630315
D112: Nov-Dec 22 | E112: -0.69327074 | F112: Lowest Food Inflation
D113: Dec-Jan 22-23 | E113: 0.44754716
...

Sheet Dashboard
A1: CPI INFLATION DASHBOARD
B57: YEAR 2021 | F57: YEAR 2022 | J57: YEAR 2023 | M57: After using correl function we can see the correlation between import crude oil products and all other categories for years 2021,2022 and 2023(May).
B59: Categories | C59: Correlation | F59: Categories | G59: Correlation | J59: Categories | K59: Correlation
B60: Cereals and products | C60: 0.81699357 | F60: Cereals and products | G60: -0.15696311 | J60: Cereals and products | K60: 0.22379098
B61: Meat and fish | C61: 0.50126055 | F61: Meat and fish | G61: 0.40826708 | J61: Meat and fish | K61: -0.14594732
B62: Egg | C62: 0.15112502 | F62: Egg | G62: -0.0048156446 | J62: Egg | K62: 0.80416226 | M62: For year 2021,2022 egg correlation was very low but in 2023 there is a sudden increase in it and same goes for Oil and Fats and more fluctuations are there we can see.
B63: Milk and products | C63: 0.93318417 | F63: Milk and products | G63: -0.12746125 | J63: Milk and products | K63: -0.79136513
B64: Oils and fats | C64: -0.25893237 | F64: Oils and fats | G64: -0.70207792 | J64: Oils and fats | K64: 0.77348678
B65: Fruits | C65: -0.030115714 | F65: Fruits | G65: 0.76047744 | J65: Fruits | K65: -0.86396579
B66: Vegetables | C66: 0.19750069 | F66: Vegetables | G66: 0.44975595 | J66: Vegetables | K66: -0.4287099
B67: Pulses and products | C67: 0.94291481 | F67: Pulses and products | G67: 0.63090812 | J67: Pulses and products | K67: -0.62974798
B68: Sugar and Confectionery | C68: 0.85638559 | F68: Sugar and Confectionery | G68: 0.39141364 | J68: Sugar and Confectionery | K68: -0.34707122
B69: Spices | C69: 0.91098685 | F69: Spices | G69: 0.59661486 | J69: Spices | K69: -0.62314606
B70: Non-alcoholic beverages | C70: 0.87920746 | F70: Non-alcoholic beverages | G70: 0.71904047 | J70: Non-alcoholic beverages | K70: -0.79373492
B71: Prepared meals, snacks, sweets etc. | C71: 0.88831699 | F71: Prepared meals, snacks, sweets etc. | G71: 0.67873305 | J71: Prepared meals, snacks, sweets etc. | K71: -0.77383696
B72: Food and beverages | C72: 0.75926791 | F72: Food and beverages | G72: 0.61381144 | J72: Food and beverages | K72: -0.63951288
B73: Pan, tobacco and intoxicants | C73: 0.94840292 | F73: Pan, tobacco and intoxicants | G73: 0.75866476 | J73: Pan, tobacco and intoxicants | K73: -0.83445382
B74: Clothing | C74: 0.89028187 | F74: Clothing | G74: 0.71850763 | J74: Clothing | K74: -0.83817572
... B84: Housing | C84: 0.89722877 | F84: Housing | G84: 0.77450075 | J84: Housing | K84: -0.84075344

Sheet Cleaned Data
A1: Sector | B1: Year | C1: Month | D1: Cereals and products | E1: Meat and fish | F1: Egg | G1: Milk and products | H1: Oils and fats | I1: Fruits | J1: Vegetables | K1: Pulses and products | L1: Sugar and Confectionery | M1: Spices | N1: Non-alcoholic beverages | O1: Prepared meals, snacks, sweets etc. | P1: Foods | Q1: Food and beverages | R1: Pan, tobacco and intoxicants | S1: Luxury | T1: Clothing | U1: Footwear | V1: Clothings | W1: Clothing and footwear | X1: Housing | Y1: Housing Goods | Z1: Fuel and light | AA1: Household goods and services | AB1: Health | AC1: Transport and communication | AD1: Recreation and amusement | AE1: Education | AF1: Personal care and effects | AG1: Miscellaneous | AH1: General index | AI1: Essential Services | AJ1: Essential Services1
A2: Rural | B2: 2013 | C2: January | D2: 107.5 | E2: 106.3 | F2: 108.1 | G2: 104.9 | H2: 106.1 | I2: 103.9 | J2: 101.9 | K2: 106.1 | L2: 106.8 | M2: 103.1 | N2: 104.8 | O2: 106.7 | P2: =SUM(O2,M2,L2,K2,J2,I2,H2,G2,F2,E2,D2,Q2) -> 1266.9 | Q2: 105.5 | R2: 105.1 | S2: =SUM(R2,N2,AD2,AF2) -> 418 | T2: 106.5 | U2: 105.8 | V2: =SUM(U2,T2,W2) -> 318.7 | W2: 106.4 | X2: 100.3 | Y2: =SUM(X2,AA2) -> 205.1 | Z2: 105.5 | AA2: 104.8 | AB2: 104 | AC2: 103.3 | AD2: 103.4 | AE2: 103.8 | AF2: 104.7 | AG2: 104 | AH2: 105.1 | AI2: =SUM('Cleaned Data'!AC2,'Cleaned Data'!AE2,'Cleaned Data'!Z2,'Cleaned Data'!AA2) -> 417.4 | AJ2: =AVERAGE(AE2,AC2,AA2,Z2) -> 104.35
A3: Urban | B3: 2013 | C3: January | D3: 110.5 | E3: 109.1 | F3: 113 | G3: 103.6 | H3: 103.4 | I3: 102.3 | J3: 102.9 | K3: 105.8 | L3: 105.1 | M3: 101.8 | N3: 105.1 | O3: 107.9 | P3: =SUM(O3,M3,L3,K3,J3,I3,H3,G3,F3,E3,D3,Q3) -> 1271.3 | Q3: 105.9 | R3: 105.2 | S3: =SUM(R3,N3,AD3,AF3) -> 417.5 | T3: 105.9 | U3: 105 | V3: =SUM(U3,T3,W3) -> 316.7 | W3: 105.8 | X3: 100.3 | Y3: =SUM(X3,AA3) -> 205.1 | Z3: 105.4 | AA3: 104.8 | AB3: 104.1 | AC3: 103.2 | AD3: 102.9 | AE3: 103.5 | AF3: 104.3 | AG3: 103.7 | AH3: 104 | AI3: =SUM('Cleaned Data'!AC3,'Cleaned Data'!AE3,'Cleaned Data'!Z3,'Cleaned Data'!AA3) -> 416.9 | AJ3: =AVERAGE(AE3,AC3,AA3,Z3) -> 104.225
A4: Rural+Urban | B4: 2013 | C4: January | D4: 108.4 | E4: 107.3 | F4: 110 | G4: 104.4 | H4: 105.1 | I4: 103.2 | J4: 102.2 | K4: 106 | L4: 106.2 | M4: 102.7 | N4: 104.9 | O4: 107.3 | P4: =SUM(O4,M4,L4,K4,J4,I4,H4,G4,F4,E4,D4,Q4) -> 1268.4 | Q4: 105.6 | R4: 105.1 | S4: =SUM(R4,N4,AD4,AF4) -> 417.6 | T4: 106.3 | U4: 105.5 | V4: =SUM(U4,T4,W4) -> 318 | W4: 106.2 | X4: 100.3 | Y4: =SUM(X4,AA4) -> 205.1 | Z4: 105.5 | AA4: 104.8 | AB4: 104 | AC4: 103.2 | AD4: 103.1 | AE4: 103.6 | AF4: 104.5 | AG4: 103.9 | AH4: 104.6 | AI4: =SUM('Cleaned Data'!AC4,'Cleaned Data'!AE4,'Cleaned Data'!Z4,'Cleaned Data'!AA4) -> 417.1 | AJ4: =AVERAGE(AE4,AC4,AA4,Z4) -> 104.275
A5: Rural | B5: 2013 | C5: February | D5: 109.2 | E5: 108.7 | F5: 110.2 | G5: 105.4 | H5: 106.7 | I5: 104 | J5: 102.4 | K5: 105.9 | L5: 105.7 | M5: 103.1 | N5: 105.1 | O5: 107.7 | P5: =SUM(O5,M5,L5,K5,J5,I5,H5,G5,F5,E5,D5,Q5) -> 1275.3 | Q5: 106.3 | R5: 105.6 | S5: =SUM(R5,N5,AD5,AF5) -> 419.3 | T5: 107.1 | U5: 106.3 | V5: =SUM(U5,T5,W5) -> 320.4 | W5: 107 | X5: 100.4 | Y5: =SUM(X5,AA5) -> 205.6 | Z5: 106.2 | AA5: 105.2 | AB5: 104.4 | AC5: 103.9 | AD5: 104 | AE5: 104.1 | AF5: 104.6 | AG5: 104.4 | AH5: 105.8 | AI5: =SUM('Cleaned Data'!AC5,'Cleaned Data'!AE5,'Cleaned Data'!Z5,'Cleaned Data'!AA5) -> 419.4 | AJ5: =AVERAGE(AE5,AC5,AA5,Z5) -> 104.85
A6: Urban | B6: 2013 | C6: February | D6: 112.9 | E6: 112.9 | F6: 116.9 | G6: 104 | H6: 103.5 | I6: 103.1 | J6: 104.9 | K6: 104.1 | L6: 103.8 | M6: 102.3 | N6: 106 | O6: 109 | P6: =SUM(O6,M6,L6,K6,J6,I6,H6,G6,F6,E6,D6,Q6) -> 1284.6 | Q6: 107.2 | R6: 106 | S6: =SUM(R6,N6,AD6,AF6) -> 419.6 | T6: 106.6 | U6: 105.5 | V6: =SUM(U6,T6,W6) -> 318.5 | W6: 106.4 | X6: 100.4 | Y6: =SUM(X6,AA6) -> 205.6 | Z6: 105.7 | AA6: 105.2 | AB6: 104.7 | AC6: 104.4 | AD6: 103.3 | AE6: 103.7 | AF6: 104.3 | AG6: 104.3 | AH6: 104.7 | AI6: =SUM('Cleaned Data'!AC6,'Cleaned Data'!AE6,'Cleaned Data'!Z6,'Cleaned Data'!AA6) -> 419 | AJ6: =AVERAGE(AE6,AC6,AA6,Z6) -> 104.75
A7: Rural+Urban | B7: 2013 | C7: February | D7: 110.4 | E7: 110.2 | F7: 112.8 | G7: 104.9 | H7: 105.5 | I7: 103.6 | J7: 103.2 | K7: 105.3 | L7: 105.1 | M7: 102.8 | N7: 105.5 | O7: 108.3 | P7: =SUM(O7,M7,L7,K7,J7,I7,H7,G7,F7,E7,D7,Q7) -> 1278.7 | Q7: 106.6 | R7: 105.7 | S7: =SUM(R7,N7,AD7,AF7) -> 419.3 | T7: 106.9 | U7: 106 | V7: =SUM(U7,T7,W7) -> 319.7 | W7: 106.8 | X7: 100.4 | Y7: =SUM(X7,AA7) -> 205.6 | Z7: 106 | AA7: 105.2 | AB7: 104.5 | AC7: 104.2 | AD7: 103.6 | AE7: 103.9 | AF7: 104.5 | AG7: 104.4 | AH7: 105.3 | AI7: =SUM('Cleaned Data'!AC7,'Cleaned Data'!AE7,'Cleaned Data'!Z7,'Cleaned Data'!AA7) -> 419.3 | AJ7: =AVERAGE(AE7,AC7,AA7,Z7) -> 104.825
A8: Rural | B8: 2013 | C8: March | D8: 110.2 | E8: 108.8 | F8: 109.9 | G8: 105.6 | H8: 106.2 | I8: 105.7 | J8: 101.4 | K8: 105.7 | L8: 105 | M8: 103.3 | N8: 105.6 | O8: 108.2 | P8: =SUM(O8,M8,L8,K8,J8,I8,H8,G8,F8,E8,D8,Q8) -> 1276.6 | Q8: 106.6 | R8: 106.5 | S8: =SUM(R8,N8,AD8,AF8) -> 420.4 | T8: 107.6 | U8: 106.8 | V8: =SUM(U8,T8,W8) -> 321.9 | W8: 107.5 | X8: 100.4 | Y8: =SUM(X8,AA8) -> 206 | Z8: 106.1 | AA8: 105.6 | AB8: 104.7 | AC8: 104.6 | AD8: 104 | AE8: 104.3 | AF8: 104.3 | AG8: 104.6 | AH8: 106 | AI8: =SUM('Cleaned Data'!AC8,'Cleaned Data'!AE8,'Cleaned Data'!Z8,'Cleaned Data'!AA8) -> 420.6 | AJ8: =AVERAGE(AE8,AC8,AA8,Z8) -> 105.15
A9: Urban | B9: 2013 | C9: March | D9: 113.9 | E9: 111.4 | F9: 113.2 | G9: 104.3 | H9: 102.7 | I9: 104.9 | J9: 103.8 | K9: 103.5 | L9: 102.6 | M9: 102.4 | N9: 107 | O9: 109.8 | P9: =SUM(O9,M9,L9,K9,J9,I9,H9,G9,F9,E9,D9,Q9) -> 1279.8 | Q9: 107.3 | R9: 106.8 | S9: =SUM(R9,N9,AD9,AF9) -> 421.5 | T9: 107.2 | U9: 106 | V9: =SUM(U9,T9,W9) -> 320.2 | W9: 107 | X9: 100.4 | Y9: =SUM(X9,AA9) -> 206.1 | Z9: 106 | AA9: 105.7 | AB9: 105.2 | AC9: 105.5 | AD9: 103.5 | AE9: 103.8 | AF9: 104.2 | AG9: 104.9 | AH9: 105 | AI9: =SUM('Cleaned Data'!AC9,'Cleaned Data'!AE9,'Cleaned Data'!Z9,'Cleaned Data'!AA9) -> 421 | AJ9: =AVERAGE(AE9,AC9,AA9,Z9) -> 105.25
A10: Rural+Urban | B10: 2013 | C10: March | D10: 111.4 | E10: 109.7 | F10: 111.2 | G10: 105.1 | H10: 104.9 | I10: 105.3 | J10: 102.2 | K10: 105 | L10: 104.2 | M10: 103 | N10: 106.2 | O10: 108.9 | P10: =SUM(O10,M10,L10,K10,J10,I10,H10,G10,F10,E10,D10,Q10) -> 1277.8 | Q10: 106.9 | R10: 106.6 | S10: =SUM(R10,N10,AD10,AF10) -> 420.8 | T10: 107.4 | U10: 106.5 | V10: =SUM(U10,T10,W10) -> 321.2 | W10: 107.3 | X10: 100.4 | Y10: =SUM(X10,AA10) -> 206 | Z10: 106.1 | AA10: 105.6 | AB10: 104.9 | AC10: 105.1 | AD10: 103.7 | AE10: 104 | AF10: 104.3 | AG10: 104.7 | AH10: 105.5 | AI10: =SUM('Cleaned Data'!AC10,'Cleaned Data'!AE10,'Cleaned Data'!Z10,'Cleaned Data'!AA10) -> 420.8 | AJ10: =AVERAGE(AE10,AC10,AA10,Z10) -> 105.2
A11: Rural | B11: 2013 | C11: April | D11: 110.2 | E11: 109.5 | F11: 106.9 | G11: 106.3 | H11: 105.7 | I11: 108.3 | J11: 103.4 | K11: 105.7 | L11: 104.2 | M11: 103.2 | N11: 106.5 | O11: 108.8 | P11: =SUM(O11,M11,L11,K11,J11,I11,H11,G11,F11,E11,D11,Q11) -> 1279.3 | Q11: 107.1 | R11: 107.1 | S11: =SUM(R11,N11,AD11,AF11) -> 420.8 | T11: 108.1 | U11: 107.4 | V11: =SUM(U11,T11,W11) -> 323.5 | W11: 108 | X11: 100.5 | Y11: =SUM(X11,AA11) -> 206.6 | Z11: 106.5 | AA11: 106.1 | AB11: 105.1 | AC11: 104.4 | AD11: 104.5 | AE11: 104.8 | AF11: 102.7 | AG11: 104.6 | AH11: 106.4 | AI11: =SUM('Cleaned Data'!AC11,'Cleaned Data'!AE11,'Cleaned Data'!Z11,'Cleaned Data'!AA11) -> 421.8 | AJ11: =AVERAGE(AE11,AC11,AA11,Z11) -> 105.45
A12: Urban | B12: 2013 | C12: April | D12: 114.6 | E12: 113.4 | F12: 106 | G12: 104.7 | H12: 102.1 | I12: 109.5 | J12: 109.7 | K12: 104.6 | L12: 102 | M12: 103.5 | N12: 108.2 | O12: 110.6 | P12: =SUM(O12,M12,L12,K12,J12,I12,H12,G12,F12,E12,D12,Q12) -> 1289.5 | Q12: 108.8 | R12: 108.5 | S12: =SUM(R12,N12,AD12,AF12) -> 423.9 | T12: 107.9 | U12: 106.4 | V12: =SUM(U12,T12,W12) -> 322 | W12: 107.7 | X12: 100.5 | Y12: =SUM(X12,AA12) -> 207 | Z12: 106.4 | AA12: 106.5 | AB12: 105.7 | AC12: 105 | AD12: 104 | AE12: 105.2 | AF12: 103.2 | AG12: 105.1 | AH12: 105.7 | AI12: =SUM('Cleaned Data'!AC12,'Cleaned Data'!AE12,'Cleaned Data'!Z12,'Cleaned Data'!AA12) -> 423.1 | AJ12: =AVERAGE(AE12,AC12,AA12,Z12) -> 105.775
A13: Rural+Urban | B13: 2013 | C13: April | D13: 111.6 | E13: 110.9 | F13: 106.6 | G13: 105.7 | H13: 104.4 | I13: 108.9 | J13: 105.5 | K13: 105.3 | L13: 103.5 | M13: 103.3 | N13: 107.2 | O13: 109.6 | P13: =SUM(O13,M13,L13,K13,J13,I13,H13,G13,F13,E13,D13,Q13) -> 1283 | Q13: 107.7 | R13: 107.5 | S13: =SUM(R13,N13,AD13,AF13) -> 421.8 | T13: 108 | U13: 107 | V13: =SUM(U13,T13,W13) -> 322.9 | W13: 107.9 | X13: 100.5 | Y13: =SUM(X13,AA13) -> 206.8 | Z13: 106.5 | AA13: 106.3 | AB13: 105.3 | AC13: 104.7 | AD13: 104.2 | AE13: 105 | AF13: 102.9 | AG13: 104.8 | AH13: 106.1 | AI13: =SUM('Cleaned Data'!AC13,'Cleaned Data'!AE13,'Cleaned Data'!Z13,'Cleaned Data'!AA13) -> 422.5 | AJ13: =AVERAGE(AE13,AC13,AA13,Z13) -> 105.625
... A142: Rural+Urban | B142: 2016 | C142: November | D142: 131.4 | E142: 137.8 | F142: 132 | G142: 135 | H142: 118 | I142: 134.1 | J142: 141.9 | K142: 171.7 | L142: 114.1 | M142: 139.7 | N142: 126.2 | O142: 141.8 | P142: =SUM(O142,M142,L142,K142,J142,I142,H142,G142,F142,E142,D142,Q142) -> 1633.6 | Q142: 136.1 | R142: 142 | S142: =SUM(R142,N142,AD142,AF142) -> 514.8 | T142: 135.8 | U142: 129.3 | V142: =SUM(U142,T142,W142) -> 400.1 | W142: 135 | X142: 129.1 | Y142: =SUM(X142,AA142) -> 257.7 | Z142: 125 | AA142: 128.6 | AB142: 126.4 | AC142: 115.7 | AD142: 124 | AE142: 132.8 | AF142: 122.6 | AG142: 123.8 | AH142: 131.2 | AI142: =SUM('Cleaned Data'!AC142,'Cleaned Data'!AE142,'Cleaned Data'!Z142,'Cleaned Data'!AA142) -> 502.1 | AJ142: =AVERAGE(AE142,AC142,AA142,Z142) -> 125.525
A143: Rural | B143: 2016 | C143: December | D143: 132.6 | E143: 137.3 | F143: 131.6 | G143: 136.3 | H143: 121.6 | I143: 135.6 | J143: 127.5 | K143: 167.9 | L143: 113.8 | M143: 137.5 | N143: 129.1 | O143: 143.6 | P143: =SUM(O143,M143,L143,K143,J143,I143,H143,G143,F143,E143,D143,Q143) -> 1620 | Q143: 134.7 | R143: 142.4 | S143: =SUM(R143,N143,AD143,AF143) -> 520.7 | T143: 140.4 | U143: 135.2 | V143: =SUM(U143,T143,W143) -> 415.3 | W143: 139.7 | X143: 128..5 | Y143: =SUM(X143,AA143) -> 132.9 | Z143: 132 | AA143: 132.9 | AB143: 129.7 | AC143: 118.6 | AD143: 127.3 | AE143: 134.2 | AF143: 121.9 | AG143: 126.3 | AH143: 132.8 | AI143: =SUM('Cleaned Data'!AC143,'Cleaned Data'!AE143,'Cleaned Data'!Z143,'Cleaned Data'!AA143) -> 517.7 | AJ143: =AVERAGE(AE143,AC143,AA143,Z143) -> 129.425
A144: Urban | B144: 2016 | C144: December | D144: 131.6 | E144: 138.2 | F144: 134.9 | G144: 133.1 | H144: 113.5 | I144: 129.3 | J144: 121.1 | K144: 170.3 | L144: 115.5 | M144: 145.5 | N144: 123.1 | O144: 140.9 | P144: =SUM(O144,M144,L144,K144,J144,I144,H144,G144,F144,E144,D144,Q144) -> 1606.7 | Q144: 132.8 | R144: 145 | S144: =SUM(R144,N144,AD144,AF144) -> 509.8 | T144: 130 | U144: 122.2 | V144: =SUM(U144,T144,W144) -> 381 | W144: 128.8 | X144: 128.5 | Y144: =SUM(X144,AA144) -> 253.5 | Z144: 117.8 | AA144: 125 | AB144: 122.3 | AC144: 113.7 | AD144: 121.8 | AE144: 132.3 | AF144: 119.9 | AG144: 121.4 | AH144: 127.6 | AI144: =SUM('Cleaned Data'!AC144,'Cleaned Data'!AE144,'Cleaned Data'!Z144,'Cleaned Data'!AA144) -> 488.8 | AJ144: =AVERAGE(AE144,AC144,AA144,Z144) -> 122.2
A145: Rural+Urban | B145: 2016 | C145: December | D145: 132.3 | E145: 137.6 | F145: 132.9 | G145: 135.1 | H145: 118.6 | I145: 132.7 | J145: 125.3 | K145: 168.7 | L145: 114.4 | M145: 140.2 | N145: 126.6 | O145: 142.3 | P145: =SUM(O145,M145,L145,K145,J145,I145,H145,G145,F145,E145,D145,Q145) -> 1614.1 | Q145: 134 | R145: 143.1 | S145: =SUM(R145,N145,AD145,AF145) -> 515 | T145: 136.3 | U145: 129.8 | V145: =SUM(U145,T145,W145) -> 401.5 | W145: 135.4 | X145: 128.5 | Y145: =SUM(X145,AA145) -> 257.7 | Z145: 126.6 | AA145: 129.2 | AB145: 126.9 | AC145: 116 | AD145: 124.2 | AE145: 133.1 | AF145: 121.1 | AG145: 123.9 | AH145: 130.4 | AI145: =SUM('Cleaned Data'!AC145,'Cleaned Data'!AE145,'Cleaned Data'!Z145,'Cleaned Data'!AA145) -> 504.9 | AJ145: =AVERAGE(AE145,AC145,AA145,Z145) -> 126.225
A146: Rural | B146: 2017 | C146: January | D146: 133.1 | E146: 137.8 | F146: 131.9 | G146: 136.7 | H146: 122 | I146: 136 | J146: 119.8 | K146: 161.7 | L146: 114.8 | M146: 136.9 | N146: 129 | O146: 143.9 | P146: =SUM(O146,M146,L146,K146,J146,I146,H146,G146,F146,E146,D146,Q146) -> 1608.3 | Q146: 133.7 | R146: 143.1 | S146: =SUM(R146,N146,AD146,AF146) -> 521.4 | T146: 140.7 | U146: 135.8 | V146: =SUM(U146,T146,W146) -> 416.5 | W146: 140 | X146: 129.6 | Y146: =SUM(X146,AA146) -> 262.8 | Z146: 132.1 | AA146: 133.2 | AB146: 129.9 | AC146: 119.1 | AD146: 127 | AE146: 134.6 | AF146: 122.3 | AG146: 126.6 | AH146: 132.4 | AI146: =SUM('Cleaned Data'!AC146,'Cleaned Data'!AE146,'Cleaned Data'!Z146,'Cleaned Data'!AA146) -> 519 | AJ146: =AVERAGE(AE146,AC146,AA146,Z146) -> 129.75
A147: Urban | B147: 2017 | C147: January | D147: 132.2 | E147: 138.9 | F147: 132.6 | G147: 133.1 | H147: 114 | I147: 129.6 | J147: 118.7 | K147: 155.1 | L147: 117.3 | M147: 144.9 | N147: 123.2 | O147: 141.6 | P147: =SUM(O147,M147,L147,K147,J147,I147,H147,G147,F147,E147,D147,Q147) -> 1590 | Q147: 132 | R147: 145.6 | S147: =SUM(R147,N147,AD147,AF147) -> 511.7 | T147: 130.2 | U147: 122.3 | V147: =SUM(U147,T147,W147) -> 381.5 | W147: 129 | X147: 129.6 | Y147: =SUM(X147,AA147) -> 254.7 | Z147: 118 | AA147: 125.1 | AB147: 122.6 | AC147: 115.2 | AD147: 122 | AE147: 132.4 | AF147: 120.9 | AG147: 122.1 | AH147: 127.8 | AI147: =SUM('Cleaned Data'!AC147,'Cleaned Data'!AE147,'Cleaned Data'!Z147,'Cleaned Data'!AA147) -> 490.7 | AJ147: =AVERAGE(AE147,AC147,AA147,Z147) -> 122.675
A148: Rural+Urban | B148: 2017 | C148: January | D148: 132.8 | E148: 138.2 | F148: 132.2 | G148: 135.4 | H148: 119.1 | I148: 133 | J148: 119.4 | K148: 159.5 | L148: 115.6 | M148: 139.6 | N148: 126.6 | O148: 142.8 | P148: =SUM(O148,M148,L148,K148,J148,I148,H148,G148,F148,E148,D148,Q148) -> 1600.7 | Q148: 133.1 | R148: 143.8 | S148: =SUM(R148,N148,AD148,AF148) -> 516.3 | T148: 136.6 | U148: 130.2 | V148: =SUM(U148,T148,W148) -> 402.4 | W148: 135.6 | X148: 129.6 | Y148: =SUM(X148,AA148) -> 259 | Z148: 126.8 | AA148: 129.4 | AB148: 127.1 | AC148: 117 | AD148: 124.2 | AE148: 133.3 | AF148: 121.7 | AG148: 124.4 | AH148: 130.3 | AI148: =SUM('Cleaned Data'!AC148,'Cleaned Data'!AE148,'Cleaned Data'!Z148,'Cleaned Data'!AA148) -> 506.5 | AJ148: =AVERAGE(AE148,AC148,AA148,Z148) -> 126.625
A149: Rural | B149: 2017 | C149: February | D149: 133.3 | E149: 138.3 | F149: 129.3 | G149: 137.2 | H149: 122.1 | I149: 138.7 | J149: 119.1 | K149: 156.9 | L149: 116.2 | M149: 136 | N149: 129.4 | O149: 144.4 | P149: =SUM(O149,M149,L149,K149,J149,I149,H149,G149,F149,E149,D149,Q149) -> 1605.1 | Q149: 133.6 | R149: 143.7 | S149: =SUM(R149,N149,AD149,AF149) -> 524 | T149: 140.9 | U149: 135.8 | V149: =SUM(U149,T149,W149) -> 416.9 | W149: 140.2 | X149: 130.5 | Y149: =SUM(X149,AA149) -> 264.1 | Z149: 133.2 | AA149: 133.6 | AB149: 130.1 | AC149: 119.5 | AD149: 127.7 | AE149: 134.9 | AF149: 123.2 | AG149: 127 | AH149: 132.6 | AI149: =SUM('Cleaned Data'!AC149,'Cleaned Data'!AE149,'Cleaned Data'!Z149,'Cleaned Data'!AA149) -> 521.2 | AJ149: =AVERAGE(AE149,AC149,AA149,Z149) -> 130.3
A150: Urban | B150: 2017 | C150: February | D150: 132.8 | E150: 139.8 | F150: 129.3 | G150: 133.5 | H150: 114.3 | I150: 131.4 | J150: 120.2 | K150: 143.1 | L150: 119.5 | M150: 144 | N150: 123.4 | O150: 141.9 | P150: =SUM(O150,M150,L150,K150,J150,I150,H150,G150,F150,E150,D150,Q150) -> 1581.9 | Q150: 132.1 | R150: 146.3 | S150: =SUM(R150,N150,AD150,AF150) -> 513.6 | T150: 130.5 | U150: 122.5 | V150: =SUM(U150,T150,W150) -> 382.3 | W150: 129.3 | X150: 130.5 | Y150: =SUM(X150,AA150) -> 255.8 | Z150: 119.2 | AA150: 125.3 | AB150: 122.9 | AC150: 115.5 | AD150: 122.2 | AE150: 132.4 | AF150: 121.7 | AG150: 122.4 | AH150: 128.2 | AI150: =SUM('Cleaned Data'!AC150,'Cleaned Data'!AE150,'Cleaned Data'!Z150,'Cleaned Data'!AA150) -> 492.4 | AJ150: =AVERAGE(AE150,AC150,AA150,Z150) -> 123.1
A151: Rural+Urban | B151: 2017 | C151: February | D151: 133.1 | E151: 138.8 | F151: 129.3 | G151: 135.8 | H151: 119.2 | I151: 135.3 | J151: 119.5 | K151: 152.2 | L151: 117.3 | M151: 138.7 | N151: 126.9 | O151: 143.2 | P151: =SUM(O151,M151,L151,K151,J151,I151,H151,G151,F151,E151,D151,Q151) -> 1595.4 | Q151: 133 | R151: 144.4 | S151: =SUM(R151,N151,AD151,AF151) -> 518.5 | T151: 136.8 | U151: 130.3 | V151: =SUM(U151,T151,W151) -> 403 | W151: 135.9 | X151: 130.5 | Y151: =SUM(X151,AA151) -> 260.2 | Z151: 127.9 | AA151: 129.7 | AB151: 127.4 | AC151: 117.4 | AD151: 124.6 | AE151: 133.4 | AF151: 122.6 | AG151: 124.8 | AH151: 130.6 | AI151: =SUM('Cleaned Data'!AC151,'Cleaned Data'!AE151,'Cleaned Data'!Z151,'Cleaned Data'!AA151) -> 508.4 | AJ151: =AVERAGE(AE151,AC151,AA151,Z151) -> 127.1
A152: Rural | B152: 2017 | C152: March | D152: 133.6 | E152: 138.8 | F152: 128.8 | G152: 137.2 | H152: 121.6 | I152: 139.7 | J152: 119.7 | K152: 148 | L152: 116.9 | M152: 135.6 | N152: 129.8 | O152: 145.4 | P152: =SUM(O152,M152,L152,K152,J152,I152,H152,G152,F152,E152,D152,Q152) -> 1598.7 | Q152: 133.4 | R152: 144.2 | S152: =SUM(R152,N152,AD152,AF152) -> 525.6 | T152: 141.6 | U152: 136.2 | V152: =SUM(U152,T152,W152) -> 418.6 | W152: 140.8 | X152: 131.1 | Y152: =SUM(X152,AA152) -> 265.2 | Z152: 134.2 | AA152: 134.1 | AB152: 130.6 | AC152: 119.8 | AD152: 128.3 | AE152: 135.2 | AF152: 123.3 | AG152: 127.4 | AH152: 132.8 | AI152: =SUM('Cleaned Data'!AC152,'Cleaned Data'!AE152,'Cleaned Data'!Z152,'Cleaned Data'!AA152) -> 523.3 | AJ152: =AVERAGE(AE152,AC152,AA152,Z152) -> 130.825
A153: Urban | B153: 2017 | C153: March | D153: 132.7 | E153: 139.4 | F153: 128.4 | G153: 134.9 | H153: 114 | I153: 136.8 | J153: 122.2 | K153: 135.8 | L153: 120.3 | M153: 142.6 | N153: 123.6 | O153: 142.4 | P153: =SUM(O153,M153,L153,K153,J153,I153,H153,G153,F153,E153,D153,Q153) -> 1582.1 | Q153: 132.6 | R153: 147.5 | S153: =SUM(R153,N153,AD153,AF153) -> 515.2 | T153: 130.8 | U153: 122.8 | V153: =SUM(U153,T153,W153) -> 383.2 | W153: 129.6 | X153: 131.1 | Y153: =SUM(X153,AA153) -> 256.7 | Z153: 120.8 | AA153: 125.6 | AB153: 123.1 | AC153: 115.6 | AD153: 122.4 | AE153: 132.8 | AF153: 121.7 | AG153: 122.6 | AH153: 128.7 | AI153: =SUM('Cleaned Data'!AC153,'Cleaned Data'!AE153,'Cleaned Data'!Z153,'Cleaned Data'!AA153) -> 494.8 | AJ153: =AVERAGE(AE153,AC153,AA153,Z153) -> 123.7
A154: Rural+Urban | B154: 2017 | C154: March | D154: 133.3 | E154: 139 | F154: 128.6 | G154: 136.3 | H154: 118.8 | I154: 138.3 | J154: 120.5 | K154: 143.9 | L154: 118 | M154: 137.9 | N154: 127.2 | O154: 144 | P154: =SUM(O154,M154,L154,K154,J154,I154,H154,G154,F154,E154,D154,Q154) -> 1591.7 | Q154: 133.1 | R154: 145.1 | S154: =SUM(R154,N154,AD154,AF154) -> 519.9 | T154: 137.3 | U154: 130.6 | V154: =SUM(U154,T154,W154) -> 404.3 | W154: 136.4 | X154: 131.1 | Y154: =SUM(X154,AA154) -> 261.2 | Z154: 129.1 | AA154: 130.1 | AB154: 127.8 | AC154: 117.6 | AD154: 125 | AE154: 133.8 | AF154: 122.6 | AG154: 125.1 | AH154: 130.9 | AI154: =SUM('Cleaned Data'!AC154,'Cleaned Data'!AE154,'Cleaned Data'!Z154,'Cleaned Data'!AA154) -> 510.6 | AJ154: =AVERAGE(AE154,AC154,AA154,Z154) -> 127.65
A155: Rural | B155: 2017 | C155: April | D155: 133.2 | E155: 138.7 | F155: 127.1 | G155: 137.7 | H155: 121.3 | I155: 141.8 | J155: 121.5 | K155: 144.5 | L155: 117.4 | M155: 134.1 | N155: 130 | O155: 145.5 | P155: =SUM(O155,M155,L155,K155,J155,I155,H155,G155,F155,E155,D155,Q155) -> 1596.3 | Q155: 133.5 | R155: 144.4 | S155: =SUM(R155,N155,AD155,AF155) -> 526.4 | T155: 142.4 | U155: 136.8 | V155: =SUM(U155,T155,W155) -> 420.8 | W155: 141.6 | X155: 131.7 | Y155: =SUM(X155,AA155) -> 266 | Z155: 135 | AA155: 134.3 | AB155: 131 | AC155: 119.2 | AD155: 128.3 | AE155: 135.7 | AF155: 123.7 | AG155: 127.5 | AH155: 132.9 | AI155: =SUM('Cleaned Data'!AC155,'Cleaned Data'!AE155,'Cleaned Data'!Z155,'Cleaned Data'!AA155) -> 524.2 | AJ155: =AVERAGE(AE155,AC155,AA155,Z155) -> 131.05
... A262: Rural+Urban | B262: 2020 | C262: April | D262: 148.7 | E262: 183.62 | F262: 148.8 | G262: 155.6 | H262: 135.1 | I262: 149.9 | J262: 168.6 | K262: 150.4 | L262: 120.3 | M262: 157.1 | N262: 136.8 | O262: 161.79 | P262: =SUM(O262,M262,L262,K262,J262,I262,H262,G262,F262,E262,D262,Q262) -> 1831.31 | Q262: 151.4 | R262: 179.9 | S262: =SUM(R262,N262,AD262,AF262) -> 610.67 | T262: 152.7 | U262: 143.65 | V262: =SUM(U262,T262,W262) -> 447.72 | W262: 151.37 | X262: 155.6 | Y262: =SUM(X262,AA262) -> 303.25 | Z262: 144.1 | AA262: 147.65 | AB262: 150.7 | AC262: 136.09 | AD262: 141.55 | AE262: 157.37 | AF262: 152.42 | AG262: 147.61 | AH262: 153.38 | AI262: =SUM('Cleaned Data'!AC262,'Cleaned Data'!AE262,'Cleaned Data'!Z262,'Cleaned Data'!AA262) -> 585.21 | AJ262: =AVERAGE(AE262,AC262,AA262,Z262) -> 146.3025
A263: Rural | B263: 2020 | C263: May | D263: 146.04 | E263: 181.67 | F263: 154.52 | G263: 153.04 | H263: 139.15 | I263: 144.71 | J263: 178.83 | K263: 149.12 | L263: 114.5 | M263: 158.46 | N263: 143.9 | O263: 161.28 | P263: =SUM(O263,M263,L263,K263,J263,I263,H263,G263,F263,E263,D263,Q263) -> 1836.27 | Q263: 154.95 | R263: 178.68 | S263: =SUM(R263,N263,AD263,AF263) -> 626.22 | T263: 154.81 | U263: 149.49 | V263: =SUM(U263,T263,W263) -> 458.38 | W263: 154.08 | Y263: =SUM(X263,AA263) -> 152.01 | Z263: 148.13636 | AA263: 152.01 | AB263: 158.06364 | AC263: 141.8 | AD263: 152.3 | AE263: 161.92 | AF263: 151.34 | AG263: 151.92 | AH263: 154.56 | AI263: =SUM('Cleaned Data'!AC263,'Cleaned Data'!AE263,'Cleaned Data'!Z263,'Cleaned Data'!AA263) -> 603.86636 | AJ263: =AVERAGE(AE263,AC263,AA263,Z263) -> 150.96659
A264: Urban | B264: 2020 | C264: May | D264: 149.8 | E264: 187.25 | F264: 159.26 | G264: 152.95 | H264: 132.8 | I264: 150.28 | J264: 198.63 | K264: 149.8 | L264: 116.88 | M264: 157.13 | N264: 136.12 | O264: 162.37 | P264: =SUM(O264,M264,L264,K264,J264,I264,H264,G264,F264,E264,D264,Q264) -> 1875.63 | Q264: 158.48 | R264: 183.31 | S264: =SUM(R264,N264,AD264,AF264) -> 617.44 | T264: 149.39 | U264: 135.44 | V264: =SUM(U264,T264,W264) -> 432.1 | W264: 147.27 | Y264: =SUM(X264,AA264) -> 142.77 | Z264: 137.68182 | AA264: 142.77 | AB264: 148.07273 | AC264: 130.96 | AD264: 146.23 | AE264: 154.12 | AF264: 151.78 | AG264: 143 | AH264: 152.05 | AI264: =SUM('Cleaned Data'!AC264,'Cleaned Data'!AE264,'Cleaned Data'!Z264,'Cleaned Data'!AA264) -> 565.53182 | AJ264: =AVERAGE(AE264,AC264,AA264,Z264) -> 141.38295
A265: Rural+Urban | B265: 2020 | C265: May | D265: 147.25 | E265: 183.62 | F265: 156.36 | G265: 153 | H265: 136.83 | I265: 147.31 | J265: 185.55 | K265: 149.35 | L265: 115.3 | M265: 158.02 | N265: 140.67 | O265: 161.79 | P265: =SUM(O265,M265,L265,K265,J265,I265,H265,G265,F265,E265,D265,Q265) -> 1850.63 | Q265: 156.25 | R265: 179.9 | S265: =SUM(R265,N265,AD265,AF265) -> 614.54 | T265: 152.7 | U265: 143.65 | V265: =SUM(U265,T265,W265) -> 447.72 | W265: 151.37 | Y265: =SUM(X265,AA265) -> 147.65 | Z265: 144.16364 | AA265: 147.65 | AB265: 154.28182 | AC265: 136.09 | AD265: 141.55 | AE265: 157.37 | AF265: 152.42 | AG265: 147.61 | AH265: 153.38 | AI265: =SUM('Cleaned Data'!AC265,'Cleaned Data'!AE265,'Cleaned Data'!Z265,'Cleaned Data'!AA265) -> 585.27364 | AJ265: =AVERAGE(AE265,AC265,AA265,Z265) -> 146.31841
A266: Rural | B266: 2020 | C266: June | D266: 148.2 | E266: 190.3 | F266: 149.4 | G266: 153.3 | H266: 138.2 | I266: 143.2 | J266: 148.9 | K266: 150.3 | L266: 113.2 | M266: 159.8 | N266: 142.1 | O266: 161.8 | P266: =SUM(O266,M266,L266,K266,J266,I266,H266,G266,F266,E266,D266,Q266) -> 1808.9 | Q266: 152.3 | R266: 182.4 | S266: =SUM(R266,N266,AD266,AF266) -> 628.9 | T266: 154.7 | U266: 150 | V266: =SUM(U266,T266,W266) -> 458.8 | W266: 154.1 | X266: 154.7 | Y266: =SUM(X266,AA266) -> 306.4 | Z266: 144.9 | AA266: 151.7 | AB266: 158.2 | AC266: 141.4 | AD266: 153.2 | AE266: 161.8 | AF266: 151.2 | AG266: 151.7 | AH266: 152.7 | AI266: =SUM('Cleaned Data'!AC266,'Cleaned Data'!AE266,'Cleaned Data'!Z266,'Cleaned Data'!AA266) -> 599.8 | AJ266: =AVERAGE(AE266,AC266,AA266,Z266) -> 149.95
A267: Urban | B267: 2020 | C267: June | D267: 152.7 | E267: 197 | F267: 154.6 | G267: 153.4 | H267: 132.9 | I267: 151.8 | J267: 171.2 | K267: 152 | L267: 116.3 | M267: 158.8 | N267: 135.6 | O267: 161.7 | P267: =SUM(O267,M267,L267,K267,J267,I267,H267,G267,F267,E267,D267,Q267) -> 1859.4 | Q267: 157 | R267: 186.7 | S267: =SUM(R267,N267,AD267,AF267) -> 619 | T267: 149.1 | U267: 136.6 | V267: =SUM(U267,T267,W267) -> 432.9 | W267: 147.2 | X267: 154.7 | Y267: =SUM(X267,AA267) -> 295.1 | Z267: 137.1 | AA267: 140.4 | AB267: 148.1 | AC267: 129.3 | AD267: 144.5 | AE267: 152.5 | AF267: 152.2 | AG267: 142 | AH267: 150.8 | AI267: =SUM('Cleaned Data'!AC267,'Cleaned Data'!AE267,'Cleaned Data'!Z267,'Cleaned Data'!AA267) -> 559.3 | AJ267: =AVERAGE(AE267,AC267,AA267,Z267) -> 139.825
A268: Rural+Urban | B268: 2020 | C268: June | D268: 149.6 | E268: 192.7 | F268: 151.4 | G268: 153.3 | H268: 136.3 | I268: 147.2 | J268: 156.5 | K268: 150.9 | L268: 114.2 | M268: 159.5 | N268: 139.4 | O268: 161.8 | P268: =SUM(O268,M268,L268,K268,J268,I268,H268,G268,F268,E268,D268,Q268) -> 1827.4 | Q268: 154 | R268: 183.5 | S268: =SUM(R268,N268,AD268,AF268) -> 622.8 | T268: 152.5 | U268: 144.4 | V268: =SUM(U268,T268,W268) -> 448.3 | W268: 151.4 | X268: 154.7 | Y268: =SUM(X268,AA268) -> 301.1 | Z268: 141.9 | AA268: 146.4 | AB268: 154.4 | AC268: 135 | AD268: 148.3 | AE268: 156.4 | AF268: 151.6 | AG268: 147 | AH268: 151.8 | AI268: =SUM('Cleaned Data'!AC268,'Cleaned Data'!AE268,'Cleaned Data'!Z268,'Cleaned Data'!AA268) -> 579.7 | AJ268: =AVERAGE(AE268,AC268,AA268,Z268) -> 144.925
A269: Rural | B269: 2020 | C269: July | D269: 148.2 | E269: 190.3 | F269: 149.4 | G269: 153.3 | H269: 138.2 | I269: 143.2 | J269: 148.9 | K269: 150.3 | L269: 113.2 | M269: 159.8 | N269: 142.1 | O269: 161.8 | P269: =SUM(O269,M269,L269,K269,J269,I269,H269,G269,F269,E269,D269,Q269) -> 1808.9 | Q269: 152.3 | R269: 182.4 | S269: =SUM(R269,N269,AD269,AF269) -> 628.9 | T269: 154.7 | U269: 150 | V269: =SUM(U269,T269,W269) -> 458.8 | W269: 154.1 | X269: 154.7 | Y269: =SUM(X269,AA269) -> 306.4 | Z269: 144.9 | AA269: 151.7 | AB269: 158.2 | AC269: 141.4 | AD269: 153.2 | AE269: 161.8 | AF269: 151.2 | AG269: 151.7 | AH269: 152.7 | AI269: =SUM('Cleaned Data'!AC269,'Cleaned Data'!AE269,'Cleaned Data'!Z269,'Cleaned Data'!AA269) -> 599.8 | AJ269: =AVERAGE(AE269,AC269,AA269,Z269) -> 149.95
A270: Urban | B270: 2020 | C270: July | D270: 152.7 | E270: 197 | F270: 154.6 | G270: 153.4 | H270: 132.9 | I270: 151.8 | J270: 171.2 | K270: 152 | L270: 116.3 | M270: 158.8 | N270: 135.6 | O270: 161.7 | P270: =SUM(O270,M270,L270,K270,J270,I270,H270,G270,F270,E270,D270,Q270) -> 1859.4 | Q270: 157 | R270: 186.7 | S270: =SUM(R270,N270,AD270,AF270) -> 619 | T270: 149.1 | U270: 136.6 | V270: =SUM(U270,T270,W270) -> 432.9 | W270: 147.2 | X270: 154.7 | Y270: =SUM(X270,AA270) -> 295.1 | Z270: 137.1 | AA270: 140.4 | AB270: 148.1 | AC270: 129.3 | AD270: 144.5 | AE270: 152.5 | AF270: 152.2 | AG270: 142 | AH270: 150.8 | AI270: =SUM('Cleaned Data'!AC270,'Cleaned Data'!AE270,'Cleaned Data'!Z270,'Cleaned Data'!AA270) -> 559.3 | AJ270: =AVERAGE(AE270,AC270,AA270,Z270) -> 139.825
A271: Rural+Urban | B271: 2020 | C271: July | D271: 149.6 | E271: 192.7 | F271: 151.4 | G271: 153.3 | H271: 136.3 | I271: 147.2 | J271: 156.5 | K271: 150.9 | L271: 114.2 | M271: 159.5 | N271: 139.4 | O271: 161.8 | P271: =SUM(O271,M271,L271,K271,J271,I271,H271,G271,F271,E271,D271,Q271) -> 1827.4 | Q271: 154 | R271: 183.5 | S271: =SUM(R271,N271,AD271,AF271) -> 622.8 | T271: 152.5 | U271: 144.4 | V271: =SUM(U271,T271,W271) -> 448.3 | W271: 151.4 | X271: 154.7 | Y271: =SUM(X271,AA271) -> 301.1 | Z271: 141.9 | AA271: 146.4 | AB271: 154.4 | AC271: 135 | AD271: 148.3 | AE271: 156.4 | AF271: 151.6 | AG271: 147 | AH271: 151.8 | AI271: =SUM('Cleaned Data'!AC271,'Cleaned Data'!AE271,'Cleaned Data'!Z271,'Cleaned Data'!AA271) -> 579.7 | AJ271: =AVERAGE(AE271,AC271,AA271,Z271) -> 144.925
A272: Rural | B272: 2020 | C272: August | D272: 147.6 | E272: 187.2 | F272: 148.4 | G272: 153.3 | H272: 139.8 | I272: 146.9 | J272: 171 | K272: 149.9 | L272: 114.2 | M272: 160 | N272: 143.5 | O272: 161.5 | P272: =SUM(O272,M272,L272,K272,J272,I272,H272,G272,F272,E272,D272,Q272) -> 1835.1 | Q272: 155.3 | R272: 180.9 | S272: =SUM(R272,N272,AD272,AF272) -> 630.2 | T272: 155.1 | U272: 149.3 | V272: =SUM(U272,T272,W272) -> 458.7 | W272: 154.3 | X272: 155.5 | Y272: =SUM(X272,AA272) -> 307.4 | Z272: 145.8 | AA272: 151.9 | AB272: 158.8 | AC272: 143.6 | AD272: 152.2 | AE272: 162.7 | AF272: 153.6 | AG272: 153 | AH272: 154.7 | AI272: =SUM('Cleaned Data'!AC272,'Cleaned Data'!AE272,'Cleaned Data'!Z272,'Cleaned Data'!AA272) -> 604 | AJ272: =AVERAGE(AE272,AC272,AA272,Z272) -> 151
A273: Urban | B273: 2020 | C273: August | D273: 151.6 | E273: 197.8 | F273: 154.5 | G273: 153.4 | H273: 133.4 | I273: 154.5 | J273: 191.9 | K273: 151.3 | L273: 116.8 | M273: 160 | N273: 136.5 | O273: 163.3 | P273: =SUM(O273,M273,L273,K273,J273,I273,H273,G273,F273,E273,D273,Q273) -> 1888.4 | Q273: 159.9 | R273: 187.2 | S273: =SUM(R273,N273,AD273,AF273) -> 620.1 | T273: 150 | U273: 135.2 | V273: =SUM(U273,T273,W273) -> 433 | W273: 147.8 | X273: 155.5 | Y273: =SUM(X273,AA273) -> 300 | Z273: 138.3 | AA273: 144.5 | AB273: 148.7 | AC273: 133.9 | AD273: 141.2 | AE273: 155.5 | AF273: 155.2 | AG273: 144.8 | AH273: 152.9 | AI273: =SUM('Cleaned Data'!AC273,'Cleaned Data'!AE273,'Cleaned Data'!Z273,'Cleaned Data'!AA273) -> 572.2 | AJ273: =AVERAGE(AE273,AC273,AA273,Z273) -> 143.05
A274: Rural+Urban | B274: 2020 | C274: August | D274: 148.9 | E274: 190.9 | F274: 150.8 | G274: 153.3 | H274: 137.4 | I274: 150.4 | J274: 178.1 | K274: 150.4 | L274: 115.1 | M274: 160 | N274: 140.6 | O274: 162.3 | P274: =SUM(O274,M274,L274,K274,J274,I274,H274,G274,F274,E274,D274,Q274) -> 1854.6 | Q274: 157 | R274: 182.6 | S274: =SUM(R274,N274,AD274,AF274) -> 623.5 | T274: 153.1 | U274: 143.4 | V274: =SUM(U274,T274,W274) -> 448.2 | W274: 151.7 | X274: 155.5 | Y274: =SUM(X274,AA274) -> 303.9 | Z274: 143 | AA274: 148.4 | AB274: 155 | AC274: 138.5 | AD274: 146 | AE274: 158.5 | AF274: 154.3 | AG274: 149 | AH274: 153.9 | AI274: =SUM('Cleaned Data'!AC274,'Cleaned Data'!AE274,'Cleaned Data'!Z274,'Cleaned Data'!AA274) -> 588.4 | AJ274: =AVERAGE(AE274,AC274,AA274,Z274) -> 147.1
...
